Workbook

Sheet Patient Log
A1: DENTAL IMPLANT PATIENT DATA LOG
A2: Comprehensive Implant Tracking & Analysis System
A3: Patient ID | B3: Patient Name | C3: Date of Surgery | D3: Surgeon | E3: Tooth / Site # | F3: Arch | G3: Jaw Region | H3: Implant Brand | I3: Implant System | J3: Implant Diameter (mm) | K3: Implant Length (mm) | L3: Cover Screw | M3: Healing Abutment | N3: Bone Graft Used | O3: Membrane Used | P3: Torque Value (Ncm) | Q3: ISQ Value | R3: Follow-up Date | S3: Notes / Complications
A4: PT-001 | B4: midhilesh | C4: 45306 | D4: Dr. Garcia | E4: #14 | F4: Upper | G4: Posterior | H4: Straumann | I4: BL Roxolid | J4: 4.1 | K4: 10 | L4: Yes | M4: No | N4: Yes | O4: No | P4: 35 | Q4: 68 | R4: 45397 | S4: Excellent primary stability
A5: PT-002 | B5: Robert Chen | C5: 45313 | D5: Dr. Patel | E5: #36 | F5: Lower | G5: Posterior | H5: Nobel | I5: Active CC | J5: 4.3 | K5: 11.5 | L5: Yes | M5: No | N5: No | O5: No | P5: 40 | Q5: 72 | R5: 45404
A6: PT-003 | B6: Maria Lopez | C6: 45327 | D6: Dr. Garcia | E6: #21 | F6: Upper | G6: Anterior | H6: Straumann | I6: TL SLA | J6: 3.3 | K6: 12 | L6: Yes | M6: No | N6: No | O6: No | P6: 30 | Q6: 65 | R6: 45417 | S6: Narrow ridge, bone augmentation planned
A7: PT-004 | B7: David Kim | C7: 45334 | D7: Dr. Wong | E7: #46 | F7: Lower | G7: Posterior | H7: Dentsply | I7: XiVE S | J7: 3.8 | K7: 13 | L7: Yes | M7: No | N7: Yes | O7: Yes | P7: 45 | Q7: 75 | R7: 45424 | S7: Guided surgery used
A8: PT-005 | B8: Susan Taylor | C8: 45342 | D8: Dr. Patel | E8: #11 | F8: Upper | G8: Anterior | H8: Nobel | I8: Active CC | J8: 3.5 | K8: 10 | L8: Yes | M8: No | N8: No | O8: No | P8: 32 | Q8: 70 | R8: 45432
A9: PT-006 | B9: James Wilson | C9: 45355 | D9: Dr. Garcia | E9: #26 | F9: Upper | G9: Posterior | H9: Zimmer | I9: Tapered Screw | J9: 4.7 | K9: 11.5 | L9: Yes | M9: No | N9: Yes | O9: Yes | P9: 38 | Q9: 66 | R9: 45447 | S9: Sinus lift performed
A10: PT-007 | B10: Emily Brown | C10: 45362 | D10: Dr. Wong | E10: #45 | F10: Lower | G10: Posterior | H10: Straumann | I10: BL Roxolid | J10: 4.1 | K10: 12 | L10: Yes | M10: No | N10: No | O10: No | P10: 42 | Q10: 73 | R10: 45454
A11: PT-008 | B11: Michael Davis | C11: 45369 | D11: Dr. Garcia | E11: #16 | F11: Upper | G11: Posterior | H11: BioHorizons | I11: Tapered Internal | J11: 5 | K11: 10 | L11: Yes | M11: Yes | N11: Yes | O11: No | P11: 36 | Q11: 69 | R11: 45461 | S11: Immediate placement
A12: PT-009 | B12: Patricia Johnson | C12: 45384 | D12: Dr. Patel | E12: #31 | F12: Lower | G12: Anterior | H12: Nobel | I12: Active CC | J12: 3.5 | K12: 11.5 | L12: Yes | M12: No | N12: No | O12: No | P12: 28 | Q12: 62 | R12: 45475 | S12: Low ISQ — monitor
A13: PT-010 | B13: Christopher Lee | C13: 45391 | D13: Dr. Wong | E13: #14 | F13: Upper | G13: Posterior | H13: Straumann | I13: BL Roxolid | J13: 4.8 | K13: 10 | L13: Yes | M13: No | N13: Yes | O13: No | P13: 40 | Q13: 74 | R13: 45482 | S13: Second implant same patient
A14: PT-011 | B14: Jennifer Martinez | C14: 45398 | D14: Dr. Garcia | E14: #36 | F14: Lower | G14: Posterior | H14: Dentsply | I14: XiVE S | J14: 4.5 | K14: 13 | L14: Yes | M14: No | N14: No | O14: No | P14: 44 | Q14: 77 | R14: 45489
A15: PT-012 | B15: Daniel Anderson | C15: 45405 | D15: Dr. Patel | E15: #22 | F15: Upper | G15: Anterior | H15: Zimmer | I15: Tapered Screw | J15: 3.7 | K15: 10 | L15: Yes | M15: No | N15: No | O15: No | P15: 30 | Q15: 67 | R15: 45496
A16: PT-013 | B16: Amanda Thomas | C16: 45419 | D16: Dr. Wong | E16: #46 | F16: Lower | G16: Posterior | H16: BioHorizons | I16: Tapered Internal | J16: 4.5 | K16: 11.5 | L16: Yes | M16: No | N16: Yes | O16: Yes | P16: 38 | Q16: 71 | R16: 45511 | S16: Bone graft — xenograft
A17: PT-014 | B17: Kevin Jackson | C17: 45426 | D17: Dr. Garcia | E17: #15 | F17: Upper | G17: Posterior | H17: Straumann | I17: TL SLA | J17: 4.1 | K17: 12 | L17: Yes | M17: No | N17: No | O17: No | P17: 37 | Q17: 72 | R17: 45518
A18: PT-015 | B18: Stephanie White | C18: 45433 | D18: Dr. Patel | E18: #25 | F18: Upper | G18: Posterior | H18: Nobel | I18: Active CC | J18: 4.3 | K18: 10 | L18: Yes | M18: No | N18: Yes | O18: No | P18: 33 | Q18: 68 | R18: 45525 | S18: Thin buccal plate noted

Sheet Site Analysis
A1: IMPLANT SITE USAGE ANALYSIS
A2: Count of implants placed at each tooth site — auto-updates when new rows are added to Patient Log
A3: Tooth / Site # | B3: Arch | C3: Jaw Region | D3: Implant Count | E3: % of Total | F3: Last Surgery Date
A4: #11 | B4: Upper | C4: Anterior | D4: =COUNTIF('Patient Log'!E:E,A4) -> 1 | E4: =IFERROR(D4/SUM(D$4:D$31),0) -> 0.066666667 | F4: =IFERROR(MAXIFS('Patient Log'!C:C,'Patient Log'!E:E,A4),"")
A5: #12 | B5: Upper | C5: Anterior | D5: =COUNTIF('Patient Log'!E:E,A5) -> 0 | E5: =IFERROR(D5/SUM(D$4:D$31),0) -> 0 | F5: =IFERROR(MAXIFS('Patient Log'!C:C,'Patient Log'!E:E,A5),"")
A6: #13 | B6: Upper | C6: Anterior | D6: =COUNTIF('Patient Log'!E:E,A6) -> 0 | E6: =IFERROR(D6/SUM(D$4:D$31),0) -> 0 | F6: =IFERROR(MAXIFS('Patient Log'!C:C,'Patient Log'!E:E,A6),"")
A7: #14 | B7: Upper | C7: Posterior | D7: =COUNTIF('Patient Log'!E:E,A7) -> 2 | E7: =IFERROR(D7/SUM(D$4:D$31),0) -> 0.13333333 | F7: =IFERROR(MAXIFS('Patient Log'!C:C,'Patient Log'!E:E,A7),"")
A8: #15 | B8: Upper | C8: Posterior | D8: =COUNTIF('Patient Log'!E:E,A8) -> 1 | E8: =IFERROR(D8/SUM(D$4:D$31),0) -> 0.066666667 | F8: =IFERROR(MAXIFS('Patient Log'!C:C,'Patient Log'!E:E,A8),"")
A9: #16 | B9: Upper | C9: Posterior | D9: =COUNTIF('Patient Log'!E:E,A9) -> 1 | E9: =IFERROR(D9/SUM(D$4:D$31),0) -> 0.066666667 | F9: =IFERROR(MAXIFS('Patient Log'!C:C,'Patient Log'!E:E,A9),"")
A10: #17 | B10: Upper | C10: Posterior | D10: =COUNTIF('Patient Log'!E:E,A10) -> 0 | E10: =IFERROR(D10/SUM(D$4:D$31),0) -> 0 | F10: =IFERROR(MAXIFS('Patient Log'!C:C,'Patient Log'!E:E,A10),"")
A11: #21 | B11: Upper | C11: Anterior | D11: =COUNTIF('Patient Log'!E:E,A11) -> 1 | E11: =IFERROR(D11/SUM(D$4:D$31),0) -> 0.066666667 | F11: =IFERROR(MAXIFS('Patient Log'!C:C,'Patient Log'!E:E,A11),"")
A12: #22 | B12: Upper | C12: Anterior | D12: =COUNTIF('Patient Log'!E:E,A12) -> 1 | E12: =IFERROR(D12/SUM(D$4:D$31),0) -> 0.066666667 | F12: =IFERROR(MAXIFS('Patient Log'!C:C,'Patient Log'!E:E,A12),"")
A13: #23 | B13: Upper | C13: Anterior | D13: =COUNTIF('Patient Log'!E:E,A13) -> 0 | E13: =IFERROR(D13/SUM(D$4:D$31),0) -> 0 | F13: =IFERROR(MAXIFS('Patient Log'!C:C,'Patient Log'!E:E,A13),"")
A14: #24 | B14: Upper | C14: Posterior | D14: =COUNTIF('Patient Log'!E:E,A14) -> 0 | E14: =IFERROR(D14/SUM(D$4:D$31),0) -> 0 | F14: =IFERROR(MAXIFS('Patient Log'!C:C,'Patient Log'!E:E,A14),"")
A15: #25 | B15: Upper | C15: Posterior | D15: =COUNTIF('Patient Log'!E:E,A15) -> 1 | E15: =IFERROR(D15/SUM(D$4:D$31),0) -> 0.066666667 | F15: =IFERROR(MAXIFS('Patient Log'!C:C,'Patient Log'!E:E,A15),"")
... A31: #47 | B31: Lower | C31: Posterior | D31: =COUNTIF('Patient Log'!E:E,A31) -> 0 | E31: =IFERROR(D31/SUM(D$4:D$31),0) -> 0 | F31: =IFERROR(MAXIFS('Patient Log'!C:C,'Patient Log'!E:E,A31),"")
A32: TOTAL | D32: =SUM(D4:D31) -> 15 | E32: =SUM(E4:E31) -> 1

Sheet Dimension Analysis
A1: IMPLANT DIMENSION USAGE ANALYSIS
A2: Diameter × Length combination counts — auto-updated from Patient Log
A3: DIAMETER COUNTS
A4: Diameter (mm) | B4: Count | C4: % Share
A5: 3.3 | B5: =COUNTIF('Patient Log'!J:J,A5) -> 1 | C5: =IFERROR(B5/SUM(B$5:B$16),0) -> 0.066666667
A6: 3.5 | B6: =COUNTIF('Patient Log'!J:J,A6) -> 2 | C6: =IFERROR(B6/SUM(B$5:B$16),0) -> 0.13333333
A7: 3.7 | B7: =COUNTIF('Patient Log'!J:J,A7) -> 1 | C7: =IFERROR(B7/SUM(B$5:B$16),0) -> 0.066666667
A8: 3.8 | B8: =COUNTIF('Patient Log'!J:J,A8) -> 1 | C8: =IFERROR(B8/SUM(B$5:B$16),0) -> 0.066666667
A9: 4.1 | B9: =COUNTIF('Patient Log'!J:J,A9) -> 3 | C9: =IFERROR(B9/SUM(B$5:B$16),0) -> 0.2
A10: 4.3 | B10: =COUNTIF('Patient Log'!J:J,A10) -> 2 | C10: =IFERROR(B10/SUM(B$5:B$16),0) -> 0.13333333
A11: 4.5 | B11: =COUNTIF('Patient Log'!J:J,A11) -> 2 | C11: =IFERROR(B11/SUM(B$5:B$16),0) -> 0.13333333
A12: 4.7 | B12: =COUNTIF('Patient Log'!J:J,A12) -> 1 | C12: =IFERROR(B12/SUM(B$5:B$16),0) -> 0.066666667
A13: 4.8 | B13: =COUNTIF('Patient Log'!J:J,A13) -> 1 | C13: =IFERROR(B13/SUM(B$5:B$16),0) -> 0.066666667
A14: 5 | B14: =COUNTIF('Patient Log'!J:J,A14) -> 1 | C14: =IFERROR(B14/SUM(B$5:B$16),0) -> 0.066666667
A15: 5.5 | B15: =COUNTIF('Patient Log'!J:J,A15) -> 0 | C15: =IFERROR(B15/SUM(B$5:B$16),0) -> 0
A16: 6 | B16: =COUNTIF('Patient Log'!J:J,A16) -> 0 | C16: =IFERROR(B16/SUM(B$5:B$16),0) -> 0
A17: TOTAL | B17: =SUM(B5:B16) -> 15 | C17: =SUM(C5:C16) -> 1
A19: LENGTH COUNTS
A20: Length (mm) | B20: Count | C20: % Share
A21: 6 | B21: =COUNTIF('Patient Log'!K:K,A21) -> 0 | C21: =IFERROR(B21/SUM(B21:B30),0) -> 0
A22: 7 | B22: =COUNTIF('Patient Log'!K:K,A22) -> 0 | C22: =IFERROR(B22/SUM(B21:B30),0) -> 0
A23: 8 | B23: =COUNTIF('Patient Log'!K:K,A23) -> 0 | C23: =IFERROR(B23/SUM(B21:B30),0) -> 0
A24: 8.5 | B24: =COUNTIF('Patient Log'!K:K,A24) -> 0 | C24: =IFERROR(B24/SUM(B21:B30),0) -> 0
A25: 10 | B25: =COUNTIF('Patient Log'!K:K,A25) -> 6 | C25: =IFERROR(B25/SUM(B21:B30),0) -> 0.4
A26: 11.5 | B26: =COUNTIF('Patient Log'!K:K,A26) -> 4 | C26: =IFERROR(B26/SUM(B21:B30),0) -> 0.26666667
A27: 12 | B27: =COUNTIF('Patient Log'!K:K,A27) -> 3 | C27: =IFERROR(B27/SUM(B21:B30),0) -> 0.2
A28: 13 | B28: =COUNTIF('Patient Log'!K:K,A28) -> 2 | C28: =IFERROR(B28/SUM(B21:B30),0) -> 0.13333333
A29: 14 | B29: =COUNTIF('Patient Log'!K:K,A29) -> 0 | C29: =IFERROR(B29/SUM(B21:B30),0) -> 0
A30: 16 | B30: =COUNTIF('Patient Log'!K:K,A30) -> 0 | C30: =IFERROR(B30/SUM(B21:B30),0) -> 0
A31: TOTAL | B31: =SUM(B21:B30) -> 15 | C31: 100.0%
A34: DIAMETER × LENGTH COMBINATION MATRIX
A35: Diam \ Length | B35: 6 | C35: 7 | D35: 8 | E35: 8.5 | F35: 10 | G35: 11.5 | H35: 12 | I35: 13 | J35: 14 | K35: 16
A36: 3.3 | B36: =COUNTIFS('Patient Log'!J:J,3.3,'Patient Log'!K:K,6) -> 0 | C36: =COUNTIFS('Patient Log'!J:J,3.3,'Patient Log'!K:K,7) -> 0 | D36: =COUNTIFS('Patient Log'!J:J,3.3,'Patient Log'!K:K,8) -> 0 | E36: =COUNTIFS('Patient Log'!J:J,3.3,'Patient Log'!K:K,8.5) -> 0 | F36: =COUNTIFS('Patient Log'!J:J,3.3,'Patient Log'!K:K,10) -> 0 | G36: =COUNTIFS('Patient Log'!J:J,3.3,'Patient Log'!K:K,11.5) -> 0 | H36: =COUNTIFS('Patient Log'!J:J,3.3,'Patient Log'!K:K,12) -> 1 | I36: =COUNTIFS('Patient Log'!J:J,3.3,'Patient Log'!K:K,13) -> 0 | J36: =COUNTIFS('Patient Log'!J:J,3.3,'Patient Log'!K:K,14) -> 0 | K36: =COUNTIFS('Patient Log'!J:J,3.3,'Patient Log'!K:K,16) -> 0
A37: 3.5 | B37: =COUNTIFS('Patient Log'!J:J,3.5,'Patient Log'!K:K,6) -> 0 | C37: =COUNTIFS('Patient Log'!J:J,3.5,'Patient Log'!K:K,7) -> 0 | D37: =COUNTIFS('Patient Log'!J:J,3.5,'Patient Log'!K:K,8) -> 0 | E37: =COUNTIFS('Patient Log'!J:J,3.5,'Patient Log'!K:K,8.5) -> 0 | F37: =COUNTIFS('Patient Log'!J:J,3.5,'Patient Log'!K:K,10) -> 1 | G37: =COUNTIFS('Patient Log'!J:J,3.5,'Patient Log'!K:K,11.5) -> 1 | H37: =COUNTIFS('Patient Log'!J:J,3.5,'Patient Log'!K:K,12) -> 0 | I37: =COUNTIFS('Patient Log'!J:J,3.5,'Patient Log'!K:K,13) -> 0 | J37: =COUNTIFS('Patient Log'!J:J,3.5,'Patient Log'!K:K,14) -> 0 | K37: =COUNTIFS('Patient Log'!J:J,3.5,'Patient Log'!K:K,16) -> 0
A38: 3.7 | B38: =COUNTIFS('Patient Log'!J:J,3.7,'Patient Log'!K:K,6) -> 0 | C38: =COUNTIFS('Patient Log'!J:J,3.7,'Patient Log'!K:K,7) -> 0 | D38: =COUNTIFS('Patient Log'!J:J,3.7,'Patient Log'!K:K,8) -> 0 | E38: =COUNTIFS('Patient Log'!J:J,3.7,'Patient Log'!K:K,8.5) -> 0 | F38: =COUNTIFS('Patient Log'!J:J,3.7,'Patient Log'!K:K,10) -> 1 | G38: =COUNTIFS('Patient Log'!J:J,3.7,'Patient Log'!K:K,11.5) -> 0 | H38: =COUNTIFS('Patient Log'!J:J,3.7,'Patient Log'!K:K,12) -> 0 | I38: =COUNTIFS('Patient Log'!J:J,3.7,'Patient Log'!K:K,13) -> 0 | J38: =COUNTIFS('Patient Log'!J:J,3.7,'Patient Log'!K:K,14) -> 0 | K38: =COUNTIFS('Patient Log'!J:J,3.7,'Patient Log'!K:K,16) -> 0
A39: 3.8 | B39: =COUNTIFS('Patient Log'!J:J,3.8,'Patient Log'!K:K,6) -> 0 | C39: =COUNTIFS('Patient Log'!J:J,3.8,'Patient Log'!K:K,7) -> 0 | D39: =COUNTIFS('Patient Log'!J:J,3.8,'Patient Log'!K:K,8) -> 0 | E39: =COUNTIFS('Patient Log'!J:J,3.8,'Patient Log'!K:K,8.5) -> 0 | F39: =COUNTIFS('Patient Log'!J:J,3.8,'Patient Log'!K:K,10) -> 0 | G39: =COUNTIFS('Patient Log'!J:J,3.8,'Patient Log'!K:K,11.5) -> 0 | H39: =COUNTIFS('Patient Log'!J:J,3.8,'Patient Log'!K:K,12) -> 0 | I39: =COUNTIFS('Patient Log'!J:J,3.8,'Patient Log'!K:K,13) -> 1 | J39: =COUNTIFS('Patient Log'!J:J,3.8,'Patient Log'!K:K,14) -> 0 | K39: =COUNTIFS('Patient Log'!J:J,3.8,'Patient Log'!K:K,16) -> 0
A40: 4.1 | B40: =COUNTIFS('Patient Log'!J:J,4.1,'Patient Log'!K:K,6) -> 0 | C40: =COUNTIFS('Patient Log'!J:J,4.1,'Patient Log'!K:K,7) -> 0 | D40: =COUNTIFS('Patient Log'!J:J,4.1,'Patient Log'!K:K,8) -> 0 | E40: =COUNTIFS('Patient Log'!J:J,4.1,'Patient Log'!K:K,8.5) -> 0 | F40: =COUNTIFS('Patient Log'!J:J,4.1,'Patient Log'!K:K,10) -> 1 | G40: =COUNTIFS('Patient Log'!J:J,4.1,'Patient Log'!K:K,11.5) -> 0 | H40: =COUNTIFS('Patient Log'!J:J,4.1,'Patient Log'!K:K,12) -> 2 | I40: =COUNTIFS('Patient Log'!J:J,4.1,'Patient Log'!K:K,13) -> 0 | J40: =COUNTIFS('Patient Log'!J:J,4.1,'Patient Log'!K:K,14) -> 0 | K40: =COUNTIFS('Patient Log'!J:J,4.1,'Patient Log'!K:K,16) -> 0
A41: 4.3 | B41: =COUNTIFS('Patient Log'!J:J,4.3,'Patient Log'!K:K,6) -> 0 | C41: =COUNTIFS('Patient Log'!J:J,4.3,'Patient Log'!K:K,7) -> 0 | D41: =COUNTIFS('Patient Log'!J:J,4.3,'Patient Log'!K:K,8) -> 0 | E41: =COUNTIFS('Patient Log'!J:J,4.3,'Patient Log'!K:K,8.5) -> 0 | F41: =COUNTIFS('Patient Log'!J:J,4.3,'Patient Log'!K:K,10) -> 1 | G41: =COUNTIFS('Patient Log'!J:J,4.3,'Patient Log'!K:K,11.5) -> 1 | H41: =COUNTIFS('Patient Log'!J:J,4.3,'Patient Log'!K:K,12) -> 0 | I41: =COUNTIFS('Patient Log'!J:J,4.3,'Patient Log'!K:K,13) -> 0 | J41: =COUNTIFS('Patient Log'!J:J,4.3,'Patient Log'!K:K,14) -> 0 | K41: =COUNTIFS('Patient Log'!J:J,4.3,'Patient Log'!K:K,16) -> 0
A42: 4.5 | B42: =COUNTIFS('Patient Log'!J:J,4.5,'Patient Log'!K:K,6) -> 0 | C42: =COUNTIFS('Patient Log'!J:J,4.5,'Patient Log'!K:K,7) -> 0 | D42: =COUNTIFS('Patient Log'!J:J,4.5,'Patient Log'!K:K,8) -> 0 | E42: =COUNTIFS('Patient Log'!J:J,4.5,'Patient Log'!K:K,8.5) -> 0 | F42: =COUNTIFS('Patient Log'!J:J,4.5,'Patient Log'!K:K,10) -> 0 | G42: =COUNTIFS('Patient Log'!J:J,4.5,'Patient Log'!K:K,11.5) -> 1 | H42: =COUNTIFS('Patient Log'!J:J,4.5,'Patient Log'!K:K,12) -> 0 | I42: =COUNTIFS('Patient Log'!J:J,4.5,'Patient Log'!K:K,13) -> 1 | J42: =COUNTIFS('Patient Log'!J:J,4.5,'Patient Log'!K:K,14) -> 0 | K42: =COUNTIFS('Patient Log'!J:J,4.5,'Patient Log'!K:K,16) -> 0
A43: 4.7 | B43: =COUNTIFS('Patient Log'!J:J,4.7,'Patient Log'!K:K,6) -> 0 | C43: =COUNTIFS('Patient Log'!J:J,4.7,'Patient Log'!K:K,7) -> 0 | D43: =COUNTIFS('Patient Log'!J:J,4.7,'Patient Log'!K:K,8) -> 0 | E43: =COUNTIFS('Patient Log'!J:J,4.7,'Patient Log'!K:K,8.5) -> 0 | F43: =COUNTIFS('Patient Log'!J:J,4.7,'Patient Log'!K:K,10) -> 0 | G43: =COUNTIFS('Patient Log'!J:J,4.7,'Patient Log'!K:K,11.5) -> 1 | H43: =COUNTIFS('Patient Log'!J:J,4.7,'Patient Log'!K:K,12) -> 0 | I43: =COUNTIFS('Patient Log'!J:J,4.7,'Patient Log'!K:K,13) -> 0 | J43: =COUNTIFS('Patient Log'!J:J,4.7,'Patient Log'!K:K,14) -> 0 | K43: =COUNTIFS('Patient Log'!J:J,4.7,'Patient Log'!K:K,16) -> 0
...

Sheet Brand & Surgeon Summary
A1: BRAND & SURGEON SUMMARY
A2: Usage counts by implant brand and surgeon — auto-updated from Patient Log
A3: IMPLANT BRAND COUNTS
A4: Brand | B4: Count | C4: % Share | D4: Systems Used
A5: Straumann | B5: =COUNTIF('Patient Log'!H:H,A5) -> 5 | C5: =IFERROR(B5/SUM(B$5:B$12),0) -> 0.33333333 | D5: =IFERROR(TEXTJOIN(", ",TRUE,UNIQUE(IF('Patient Log'!H$4:H$10000=A5,'Patient Log'!I$4:I$10000,"")))&"","")
A6: Nobel | B6: =COUNTIF('Patient Log'!H:H,A6) -> 4 | C6: =IFERROR(B6/SUM(B$5:B$12),0) -> 0.26666667 | D6: =IFERROR(TEXTJOIN(", ",TRUE,UNIQUE(IF('Patient Log'!H$4:H$10000=A6,'Patient Log'!I$4:I$10000,"")))&"","")
A7: Dentsply | B7: =COUNTIF('Patient Log'!H:H,A7) -> 2 | C7: =IFERROR(B7/SUM(B$5:B$12),0) -> 0.13333333 | D7: =IFERROR(TEXTJOIN(", ",TRUE,UNIQUE(IF('Patient Log'!H$4:H$10000=A7,'Patient Log'!I$4:I$10000,"")))&"","")
A8: Zimmer | B8: =COUNTIF('Patient Log'!H:H,A8) -> 2 | C8: =IFERROR(B8/SUM(B$5:B$12),0) -> 0.13333333 | D8: =IFERROR(TEXTJOIN(", ",TRUE,UNIQUE(IF('Patient Log'!H$4:H$10000=A8,'Patient Log'!I$4:I$10000,"")))&"","")
A9: BioHorizons | B9: =COUNTIF('Patient Log'!H:H,A9) -> 2 | C9: =IFERROR(B9/SUM(B$5:B$12),0) -> 0.13333333 | D9: =IFERROR(TEXTJOIN(", ",TRUE,UNIQUE(IF('Patient Log'!H$4:H$10000=A9,'Patient Log'!I$4:I$10000,"")))&"","")
A10: Osstem | B10: =COUNTIF('Patient Log'!H:H,A10) -> 0 | C10: =IFERROR(B10/SUM(B$5:B$12),0) -> 0 | D10: =IFERROR(TEXTJOIN(", ",TRUE,UNIQUE(IF('Patient Log'!H$4:H$10000=A10,'Patient Log'!I$4:I$10000,"")))&"","")
A11: Megagen | B11: =COUNTIF('Patient Log'!H:H,A11) -> 0 | C11: =IFERROR(B11/SUM(B$5:B$12),0) -> 0 | D11: =IFERROR(TEXTJOIN(", ",TRUE,UNIQUE(IF('Patient Log'!H$4:H$10000=A11,'Patient Log'!I$4:I$10000,"")))&"","")
A12: Other | B12: =COUNTIF('Patient Log'!H:H,A12) -> 0 | C12: =IFERROR(B12/SUM(B$5:B$12),0) -> 0 | D12: =IFERROR(TEXTJOIN(", ",TRUE,UNIQUE(IF('Patient Log'!H$4:H$10000=A12,'Patient Log'!I$4:I$10000,"")))&"","")
A13: TOTAL | B13: =SUM(B5:B12) -> 15
A15: SURGEON COUNTS
A16: Surgeon | B16: Implants Placed | C16: % of Total | D16: Sites Used
A17: Dr. Garcia | B17: =COUNTIF('Patient Log'!D:D,A17) -> 6 | C17: =IFERROR(B17/SUM(B$17:B$20),0) -> 0.4 | D17: =IFERROR(TEXTJOIN(", ",TRUE,UNIQUE(IF('Patient Log'!D$4:D$10000=A17,'Patient Log'!E$4:E$10000,"")))&"","")
A18: Dr. Patel | B18: =COUNTIF('Patient Log'!D:D,A18) -> 5 | C18: =IFERROR(B18/SUM(B$17:B$20),0) -> 0.33333333 | D18: =IFERROR(TEXTJOIN(", ",TRUE,UNIQUE(IF('Patient Log'!D$4:D$10000=A18,'Patient Log'!E$4:E$10000,"")))&"","")
A19: Dr. Wong | B19: =COUNTIF('Patient Log'!D:D,A19) -> 4 | C19: =IFERROR(B19/SUM(B$17:B$20),0) -> 0.26666667 | D19: =IFERROR(TEXTJOIN(", ",TRUE,UNIQUE(IF('Patient Log'!D$4:D$10000=A19,'Patient Log'!E$4:E$10000,"")))&"","")
A20: Other | B20: =COUNTIF('Patient Log'!D:D,A20) -> 0 | C20: =IFERROR(B20/SUM(B$17:B$20),0) -> 0 | D20: =IFERROR(TEXTJOIN(", ",TRUE,UNIQUE(IF('Patient Log'!D$4:D$10000=A20,'Patient Log'!E$4:E$10000,"")))&"","")
A21: TOTAL | B21: =SUM(B17:B20) -> 15

Sheet Instructions & Key
A1: DENTAL IMPLANT LOG — INSTRUCTIONS & DATA KEY
A3: HOW TO USE THIS WORKBOOK
A5: 1. DATA ENTRY
A6: • Open the 'Patient Log' sheet to add new patient records.
A7: • Each row = one implant. If a patient receives multiple implants, add a row for each.
A8: • Dropdown menus are provided for: Arch, Jaw Region, Brand, Diameter, Length, and Yes/No fields.
A9: • Date columns use yyyy-mm-dd format.
A11: 2. ANALYSIS — AUTO-UPDATES
A12: • 'Site Analysis' — counts how many implants were placed at each tooth site (#11–#47).
A13: • 'Dimension Analysis' — counts how often each diameter and length was used, plus a combination matrix.
A14: • 'Brand & Surgeon Summary' — counts implants by brand and by surgeon.
A15: • All analysis sheets use COUNTIF/COUNTIFS formulas linked to the Patient Log — add rows and they update automatically.
... A43: • Charts in the analysis sheets use static data ranges. If many new sites/brands are added, extend the chart range manually.
